<?xml version="1.0" encoding="UTF-8"?>
<!-- Generated by org.testng.reporters.JUnitXMLReporter -->
<testsuite hostname="INsaikrisv.local" name="Command line test" tests="6" failures="1" timestamp="2 Feb 2016 17:18:37 GMT" time="5.495" errors="0">
  <testcase name="testApp4 on [Sample2Test passed=0 failed=0 skipped=0]" time="0.001" classname="com.test.sample.Sample2Test"/>
  <testcase name="testApp5 on [Sample2Test passed=0 failed=0 skipped=0]" time="0.0" classname="com.test.sample.Sample2Test"/>
  <testcase name="testApp6 on [Sample2Test passed=0 failed=0 skipped=0]" time="0.002" classname="com.test.sample.Sample2Test">
    <skipped/>
  </testcase> <!-- testApp6 on [Sample2Test passed=0 failed=0 skipped=0] -->
  <testcase name="testApp6 on [Sample2Test passed=0 failed=0 skipped=0]" time="0.001" classname="com.test.sample.Sample2Test">
    <skipped/>
  </testcase> <!-- testApp6 on [Sample2Test passed=0 failed=0 skipped=0] -->
  <testcase name="testApp6 on [Sample2Test passed=0 failed=0 skipped=0]" time="0.0" classname="com.test.sample.Sample2Test">
    <failure type="java.lang.AssertionError" message="expected [5] but found [0]">
      <![CDATA[java.lang.AssertionError: expected [5] but found [0]
	at com.test.sample.Sample2Test.testApp6(Sample2Test.java:30)
	at com.test.sample.Runner.testRunnerTestNg(Runner.java:77)
	at com.test.sample.Runner$1.run(Runner.java:27)
	at java.util.concurrent.Executors$RunnableAdapter.call(Executors.java:511)
	at java.util.concurrent.FutureTask.run(FutureTask.java:266)
	at java.util.concurrent.ThreadPoolExecutor.runWorker(ThreadPoolExecutor.java:1142)
	at java.util.concurrent.ThreadPoolExecutor$Worker.run(ThreadPoolExecutor.java:617)
	at java.lang.Thread.run(Thread.java:745)
... Removed 27 stack frames]]>
    </failure>
  </testcase> <!-- testApp6 on [Sample2Test passed=0 failed=0 skipped=0] -->
  <testcase name="testApp7 on [Sample2Test passed=0 failed=0 skipped=0]" time="0.0" classname="com.test.sample.Sample2Test"/>
</testsuite> <!-- Command line test -->
